[2025-05-19T18:39:45.077+0000] {local_task_job_runner.py:120} INFO - ::group::Pre task execution logs
[2025-05-19T18:39:45.099+0000] {taskinstance.py:2076} INFO - Dependencies all met for dep_context=non-requeueable deps ti=<TaskInstance: referential_integrity_check.run_check manual__2025-05-19T18:39:44.010286+00:00 [queued]>
[2025-05-19T18:39:45.226+0000] {taskinstance.py:2076} INFO - Dependencies all met for dep_context=requeueable deps ti=<TaskInstance: referential_integrity_check.run_check manual__2025-05-19T18:39:44.010286+00:00 [queued]>
[2025-05-19T18:39:45.226+0000] {taskinstance.py:2306} INFO - Starting attempt 1 of 1
[2025-05-19T18:39:45.239+0000] {taskinstance.py:2330} INFO - Executing <Task(PythonOperator): run_check> on 2025-05-19 18:39:44.010286+00:00
[2025-05-19T18:39:45.245+0000] {warnings.py:112} WARNING - /home/***/.local/lib/python3.12/site-packages/***/task/task_runner/standard_task_runner.py:62: DeprecationWarning: This process (pid=58) is multi-threaded, use of fork() may lead to deadlocks in the child.
  pid = os.fork()

[2025-05-19T18:39:45.246+0000] {standard_task_runner.py:64} INFO - Started process 60 to run task
[2025-05-19T18:39:45.246+0000] {standard_task_runner.py:90} INFO - Running: ['***', 'tasks', 'run', 'referential_integrity_check', 'run_check', 'manual__2025-05-19T18:39:44.010286+00:00', '--job-id', '147', '--raw', '--subdir', 'DAGS_FOLDER/referential_integrity_check.py', '--cfg-path', '/tmp/tmpxutlck58']
[2025-05-19T18:39:45.247+0000] {standard_task_runner.py:91} INFO - Job 147: Subtask run_check
[2025-05-19T18:39:45.283+0000] {task_command.py:426} INFO - Running <TaskInstance: referential_integrity_check.run_check manual__2025-05-19T18:39:44.010286+00:00 [running]> on host 4468f627a1d7
[2025-05-19T18:39:45.360+0000] {taskinstance.py:2648} INFO - Exporting env vars: AIRFLOW_CTX_DAG_OWNER='***' AIRFLOW_CTX_DAG_ID='referential_integrity_check' AIRFLOW_CTX_TASK_ID='run_check' AIRFLOW_CTX_EXECUTION_DATE='2025-05-19T18:39:44.010286+00:00' AIRFLOW_CTX_TRY_NUMBER='1' AIRFLOW_CTX_DAG_RUN_ID='manual__2025-05-19T18:39:44.010286+00:00'
[2025-05-19T18:39:45.362+0000] {taskinstance.py:430} INFO - ::endgroup::
[2025-05-19T18:39:45.373+0000] {taskinstance.py:441} INFO - ::group::Post task execution logs
[2025-05-19T18:39:45.374+0000] {taskinstance.py:2905} ERROR - Task failed with exception
Traceback (most recent call last):
  File "/home/airflow/.local/lib/python3.12/site-packages/airflow/models/taskinstance.py", line 465, in _execute_task
    result = _execute_callable(context=context, **execute_callable_kwargs)
             ^^^^^^^^^^^^^^^^^^^^^^^^^^^^^^^^^^^^^^^^^^^^^^^^^^^^^^^^^^^^^
  File "/home/airflow/.local/lib/python3.12/site-packages/airflow/models/taskinstance.py", line 432, in _execute_callable
    return execute_callable(context=context, **execute_callable_kwargs)
           ^^^^^^^^^^^^^^^^^^^^^^^^^^^^^^^^^^^^^^^^^^^^^^^^^^^^^^^^^^^^
  File "/home/airflow/.local/lib/python3.12/site-packages/airflow/models/baseoperator.py", line 401, in wrapper
    return func(self, *args, **kwargs)
           ^^^^^^^^^^^^^^^^^^^^^^^^^^^
  File "/home/airflow/.local/lib/python3.12/site-packages/airflow/operators/python.py", line 235, in execute
    return_value = self.execute_callable()
                   ^^^^^^^^^^^^^^^^^^^^^^^
  File "/home/airflow/.local/lib/python3.12/site-packages/airflow/operators/python.py", line 252, in execute_callable
    return self.python_callable(*self.op_args, **self.op_kwargs)
           ^^^^^^^^^^^^^^^^^^^^^^^^^^^^^^^^^^^^^^^^^^^^^^^^^^^^^
  File "/opt/airflow/dags/referential_integrity_check.py", line 27, in run_check_and_save_to_db
    raise ValueError("Не все параметры указаны")
ValueError: Не все параметры указаны
[2025-05-19T18:39:45.383+0000] {taskinstance.py:1206} INFO - Marking task as FAILED. dag_id=referential_integrity_check, task_id=run_check, run_id=manual__2025-05-19T18:39:44.010286+00:00, execution_date=20250519T183944, start_date=20250519T183945, end_date=20250519T183945
[2025-05-19T18:39:45.394+0000] {standard_task_runner.py:110} ERROR - Failed to execute job 147 for task run_check (Не все параметры указаны; 60)
[2025-05-19T18:39:45.419+0000] {local_task_job_runner.py:243} INFO - Task exited with return code 1
[2025-05-19T18:39:45.432+0000] {taskinstance.py:3503} INFO - 0 downstream tasks scheduled from follow-on schedule check
[2025-05-19T18:39:45.435+0000] {local_task_job_runner.py:222} INFO - ::endgroup::
